<?xml version="1.0" ?>
<sdf version='1.7'>
<model name='Cobotta'>
    <!--========================================================-->
    <!-- link_root -->
    <link name='link_root'>
    <inertial>
        <pose>0.00056 0.0223 0.04527 0 -0 0</pose>
        <!-- Massa necessaria per impedire movimento della base -->
        <mass>10000</mass>
        <inertia>
            <ixx>0.01955</ixx>
            <ixy>-0.0037</ixy>
            <ixz>0.00097</ixz>
            <iyy>0.00572002</iyy>
            <iyz>0.00387999</iyz>
            <izz>0.02018</izz>
        </inertia>
    </inertial>
    <surface>
            <friction>
                <ode>
                    <mu1>0.2</mu1>
                    <mu2>0.2</mu2>
                </ode>
            </friction>
        </surface>
    <collision name='link_root_fixed_joint_lump__base_collision_collision'>
        <pose>0 0 0 1.5708 -0 0</pose>
        <geometry>
        <mesh>
            <scale>1 1 1</scale>
            <uri>model://robot_description/meshes/coll/base.dae</uri>
        </mesh> 
        </geometry>
    </collision>
    <visual name='link_root_fixed_joint_lump__base_visual'>
        <pose>0 0 0 1.5708 -0 0</pose>
        <geometry>
        <mesh>
            <scale>1 1 1</scale>
            <uri>model://robot_description/meshes/dae/base.dae</uri>
        </mesh> 
        </geometry>
    </visual>
    </link>
    <!--========================================================-->
    <!-- joint1 -->
    <joint name='joint1' type='revolute'>
    <pose relative_to='link_root'>0 0 0.108 0 -0 0</pose>
    <parent>link_root</parent>
    <child>link_j1</child>
    <axis>
        <xyz>0 0 1</xyz>
        <limit>
            <effort>100</effort>
            <velocity>1.62490153360672</velocity>
            <lower>-2.61799387799149</lower>
            <upper>2.61799387799149</upper>
        </limit>
        <dynamics>
            <spring_reference>0</spring_reference>
            <spring_stiffness>0</spring_stiffness>
            <damping>0</damping>
            <friction>20</friction>
        </dynamics>
    </axis>
    </joint>
    <!--========================================================-->
    <!-- link_j1 -->
    <link name='link_j1'>
    <pose relative_to='joint1'>0 0 0 0 -0 0</pose>
    <inertial>
        <pose>0.00668 0 0.04965 0 -0 0</pose>
        <mass>1</mass>
        <inertia>
            <ixx>0.00068</ixx>
            <ixy>0</ixy>
            <ixz>-9e-05</ixz>
            <iyy>0.00078</iyy>
            <iyz>0</iyz>
            <izz>0.00057</izz>
        </inertia>
    </inertial>
    <surface>
            <friction>
                <ode>
                    <mu1>0.2</mu1>
                    <mu2>0.2</mu2>
                </ode>
            </friction>
        </surface>
    <collision name='link_j1_fixed_joint_lump__j2_collision_collision'>
        <pose>0 0 -0.108 1.5708 -0 0</pose>
        <geometry>
        <mesh>
            <scale>1 1 1</scale>
            <uri>model://robot_description/meshes/coll/j2.dae</uri>
        </mesh> 
        </geometry>
    </collision>
    <visual name='link_j1_fixed_joint_lump__j2_visual'>
        <pose>0 0 -0.108 1.5708 -0 0</pose>
        <geometry>
        <mesh>
            <scale>1 1 1</scale>
            <uri>model://robot_description/meshes/dae/j2.dae</uri>
        </mesh> 
        </geometry>
    </visual>
    </link>
    <!--========================================================-->
    <!-- joint2 -->
    <joint name='joint2' type='revolute'>
    <pose relative_to='link_j1'>0.062 0 0.072 3.14159 1.57079 3.14159</pose>
    <parent>link_j1</parent>
    <child>link_j2</child>
    <axis>
        <xyz>0 0 1</xyz>
        <limit>
            <effort>100</effort>
            <velocity>0.759226951263793</velocity>
            <lower>-1.0471975511966</lower>
            <upper>1.74532925199433</upper>
        </limit>
        <dynamics>
            <spring_reference>0</spring_reference>
            <spring_stiffness>0</spring_stiffness>
            <damping>0</damping>
            <friction>20</friction>
        </dynamics>
    </axis>
    </joint>
    <!--========================================================-->
    <!-- link_j2 -->
    <link name='link_j2'>
    <pose relative_to='joint2'>0 0 0 0 -0 0</pose>
    <inertial>
        <pose>-0.07592 0.02475 0.03838 0 -0 0</pose>
        <mass>1</mass>
        <inertia>
            <ixx>0.00482</ixx>
            <ixy>-8e-05</ixy>
            <ixz>-3e-05</ixz>
            <iyy>0.00462</iyy>
            <iyz>-3e-05</iyz>
            <izz>0.00075</izz>
        </inertia>
    </inertial>
    <surface>
            <friction>
                <ode>
                    <mu1>0.2</mu1>
                    <mu2>0.2</mu2>
                </ode>
            </friction>
        </surface>
    <collision name='link_j2_fixed_joint_lump__j1Starm_collision_collision'>
        <pose>0.18 0 -0.062 1.5708 -1.5708 0</pose>
        <geometry>
        <mesh>
            <scale>1 1 1</scale>
            <uri>model://robot_description/meshes/coll/j1Starm.dae</uri>
        </mesh> 
        </geometry>
    </collision>
    <visual name='link_j2_fixed_joint_lump__j1Starm_visual'>
        <pose>0.18 0 -0.062 1.5708 -1.5708 0</pose>
        <geometry>
        <mesh>
            <scale>1 1 1</scale>
            <uri>model://robot_description/meshes/dae/j1Starm.dae</uri>
        </mesh> 
        </geometry>
    </visual>
    </link>
    <!--========================================================-->
    <!-- joint3 -->
    <joint name='joint3' type='revolute'>
    <pose relative_to='link_j2'>-0.165 0 0 3.14159 -0 3.14159</pose>
<!--     <pose relative_to='link_j2'>-0.165 0 0 3.14159 -0 1.570795</pose> -->
    <parent>link_j2</parent>
    <child>link_j3</child>
    <axis>
        <xyz>0 0 -1</xyz>
        <limit>
            <effort>100</effort>
            <velocity>1.66187633381022</velocity>
            <lower>0.314159265358979</lower>
            <upper>2.44346095279206</upper>
        </limit>
        <dynamics>
            <spring_reference>0</spring_reference>
            <spring_stiffness>0</spring_stiffness>
            <damping>0</damping>
            <friction>20</friction>
        </dynamics>
    </axis>
    </joint>
    <!--========================================================-->
    <!-- link_j3 -->
    <link name='link_j3'>
    <pose relative_to='joint3'>0 0 0 0 0 1.57</pose>
    <inertial>
        <pose>0.00526 -0.02675 0.03861 0 -0 0</pose>
        <mass>1</mass>
        <inertia>
            <ixx>0.0004</ixx>
            <ixy>-3e-05</ixy>
            <ixz>1e-05</ixz>
            <iyy>0.00018</iyy>
            <iyz>4e-05</iyz>
            <izz>0.00041</izz>
        </inertia>
    </inertial>
    <surface>
            <friction>
                <ode>
                    <mu1>0.2</mu1>
                    <mu2>0.2</mu2>
                </ode>
            </friction>
        </surface>
    <collision name='link_j3_fixed_joint_lump__j34_collision_collision'>
        <pose>-0.345 0 0.062 1.5708 1.5708 0</pose>
        <geometry>
        <mesh>
            <scale>1 1 1</scale>
            <uri>model://robot_description/meshes/coll/j34.dae</uri>
        </mesh> 
        </geometry>
    </collision>
    <visual name='link_j3_fixed_joint_lump__j34_visual'>
        <pose>-0.345 0 0.062 1.5708 1.5708 0</pose>
        <geometry>
        <mesh>
            <scale>1 1 1</scale>
            <uri>model://robot_description/meshes/dae/j34.dae</uri>
        </mesh> 
        </geometry>
    </visual>
    </link>
    <!--========================================================-->
    <!-- joint4 -->
    <joint name='joint4' type='revolute'>
    <pose relative_to='link_j3'>0.012 -0.088 0.042 -1.57079 1.57079 3.14159</pose>
    <parent>link_j3</parent>
    <child>link_j4</child>
    <axis>
        <xyz>0 0 1</xyz>
        <limit>
            <effort>100</effort>
            <velocity>2.5534166956677</velocity>
            <lower>-2.96705972839036</lower>
            <upper>2.96705972839036</upper>
        </limit>
        <dynamics>
            <spring_reference>0</spring_reference>
            <spring_stiffness>0</spring_stiffness>
            <damping>0</damping>
            <friction>20</friction>
        </dynamics>
    </axis>
    </joint>
    <!--========================================================-->
    <!-- link_j4 -->
    <link name='link_j4'>
    <pose relative_to='joint4'>0 0 0 0 -0 0</pose>
    <inertial>
        <pose>-0.00143 0 0.05394 0 -0 0</pose>
        <mass>0.3</mass>
        <inertia>
            <ixx>0.038</ixx>
            <ixy>-2e-05</ixy>
            <ixz>0</ixz>
            <iyy>0.013</iyy>
            <iyz>0</iyz>
            <izz>0.039</izz>
        </inertia>
    </inertial>
    <collision name='link_j4_fixed_joint_lump__j2ndarm_collision_collision'>
        <pose>-0.02 -0.357 -0.088 0 -0 0</pose>
        <geometry>
        <mesh>
            <scale>1 1 1</scale>
            <uri>model://robot_description/meshes/coll/j2ndarm.dae</uri>
        </mesh>
        </geometry>
    </collision>
    <visual name='link_j4_fixed_joint_lump__j2ndarm_visual'>
        <pose>-0.02 -0.357 -0.088 0 -0 0</pose>
        <geometry>
        <mesh>
            <scale>1 1 1</scale>
            <uri>model://robot_description/meshes/dae/j2ndarm.dae</uri>
        </mesh>
        </geometry>
    </visual>
    </link>
    <!--========================================================-->
    <!-- joint5 -->
    <joint name='joint5' type='revolute'>
    <pose relative_to='link_j4'>-0.042 0 0.089 -1.5708 0 1.5708</pose>
    <parent>link_j4</parent>
    <child>link_j5</child>
    <axis>
        <xyz>0 0 -1</xyz>
        <limit>
            <effort>100</effort>
            <velocity>2.66948109092533</velocity>
            <lower>-1.65806278939461</lower>
            <upper>2.35619449019234</upper>
        </limit>
        <dynamics>
            <spring_reference>0</spring_reference>
            <spring_stiffness>0</spring_stiffness>
            <damping>0</damping>
            <friction>20</friction>
        </dynamics>
    </axis>
    </joint>
    <!--========================================================-->
    <!-- link_j5 -->
    <link name='link_j5'>
    <pose relative_to='joint5'>0 0 0 0 -0 0</pose>
    <inertial>
        <pose>-0.0001 -0.0084 0.01804 0 -0 0</pose>
        <mass>0.1</mass>
        <inertia>
            <ixx>9e-03</ixx>
            <ixy>-1e-05</ixy>
            <ixz>1e-05</ixz>
            <iyy>9e-03</iyy>
            <iyz>1e-03</iyz>
            <izz>7e-03</izz>
        </inertia>
    </inertial>
    <surface>
            <friction>
                <ode>
                    <mu1>0.2</mu1>
                    <mu2>0.2</mu2>
                </ode>
            </friction>
        </surface>
    <collision name='link_j5_fixed_joint_lump__j6_collision_collision'>
        <pose>-0.357 0.177 -0.022 1.5708 1.5708 0</pose>
        <geometry>
        <mesh>
            <scale>1 1 1</scale>
            <uri>model://robot_description/meshes/coll/j6.dae</uri>
        </mesh>
        </geometry>
    </collision>
    <visual name='link_j5_fixed_joint_lump__j6_visual'>
        <pose>-0.357 0.177 -0.022 1.5708 1.5708 0</pose>
        <geometry>
        <mesh>
            <scale>1 1 1</scale>
            <uri>model://robot_description/meshes/dae/j6.dae</uri>
        </mesh>
        </geometry>
    </visual>
    <collision name='link_j5_fixed_joint_lump__CAMERA_SET2_ASM_collision_collision'>
        <pose>-0.357 0.177 -0.021999 1.5708 1.5708 0</pose>
        <geometry>
        <mesh>
            <scale>1 1 1</scale>
            <uri>model://robot_description/meshes/coll/CAMERA_SET2_ASM.dae</uri>
        </mesh>
        </geometry>
    </collision>
    <visual name='link_j5_fixed_joint_lump__CAMERA_SET2_ASM_visual_1'>
        <pose>-0.357 0.177 -0.021999 1.5708 1.5708 0</pose>
        <geometry>
        <mesh>
            <scale>1 1 1</scale>
            <uri>model://robot_description/meshes/dae/CAMERA_SET2_ASM.dae</uri>
        </mesh>
        </geometry>
    </visual>

    <!-- Questa parte di codice puo' essere utilizzata per visualizzare la posizione del sensore.
    <visual name="visual">
        <pose>0.056 -0.056 0.021 -1.5708 0 -1.5708</pose>
        <geometry>
        <box>
            <size>0.05 0.05 0.05</size>
        </box>
        </geometry>
    </visual> -->


    <sensor name="camera" type="camera">
        <pose>0.056 -0.056 0.021 -1.5708 0 -1.5708</pose>
        <camera>
        <horizontal_fov>0.666716</horizontal_fov>
        <image>
            <width>960</width>
            <height>540</height>
        </image>
        <clip>
            <near>0.04</near>
            <far>1000</far>
        </clip>
        </camera>
        <always_on>1</always_on>
        <update_rate>30</update_rate>
        <visualize>true</visualize>
        <topic>camera</topic>
    </sensor>
    </link>
    <!--========================================================-->
    <!-- joint6 -->
    <joint name='joint6' type='revolute'>
    <pose relative_to='link_j5'>0 -0.04 0.0225 -1.57079 1.57079 3.14159</pose>
    <parent>link_j5</parent>
    <child>link_j6</child>
    <axis>
        <xyz>0 0 1</xyz>
        <limit>
            <effort>100</effort>
            <velocity>3.83012504350156</velocity>
            <lower>-2.96705972839036</lower>
            <upper>2.96705972839036</upper>
        </limit>
        <dynamics>
            <spring_reference>0</spring_reference>
            <spring_stiffness>0</spring_stiffness>
            <damping>0</damping>
            <friction>20</friction>
        </dynamics>
    </axis>
    </joint>
    <!--========================================================-->
    <!-- link_j6 -->
    <link name='link_j6'>
    <pose relative_to='joint6'>0 0 0 0 -0 0</pose>
    <inertial>
        <pose>-0.0005 0 0.02106 0 -0 0</pose>
        <mass>0.08</mass>
        <inertia>
            <ixx>3e-01</ixx>
            <ixy>0</ixy>
            <ixz>0</ixz>
            <iyy>4e-01</iyy>
            <iyz>0</iyz>
            <izz>3e-01</izz>
        </inertia>
    </inertial>
    <surface>
            <friction>
                <ode>
                    <mu1>0.2</mu1>
                    <mu2>0.2</mu2>
                </ode>
            </friction>
        </surface>
    <collision name='link_j6_fixed_joint_lump__hand_collision_collision'>
        <pose>-0.0005 0 0.001 0 -0 0</pose>
        <geometry>
        <mesh>
            <scale>1 1 1</scale>
            <uri>model://robot_description/meshes/coll/hand.dae</uri>
        </mesh>
        </geometry>
    </collision>
    <visual name='link_j6_fixed_joint_lump__hand_visual'>
        <pose>-0.0005 0 0.001 0 -0 0</pose>
        <geometry>
        <mesh>
            <scale>1 1 1</scale>
            <uri>model://robot_description/meshes/dae/hand.dae</uri>
        </mesh>
        </geometry>
    </visual>
    </link>
    <!--========================================================-->
    <!-- joint_left -->
    <joint name='joint_left' type='prismatic'>
    <pose relative_to='link_j6'>0.0145 0 0.0625 -1.5708 -0 -1.5708</pose>
    <parent>link_j6</parent>
    <child>link_gripper_r</child>
    <axis>
        <xyz>0 0 1</xyz>
        <limit>
            <lower>-0.015</lower>
            <upper>0</upper>
            <effort>100</effort>
            <velocity>1</velocity>
        </limit>
        <dynamics>
            <spring_reference>0</spring_reference>
            <spring_stiffness>0</spring_stiffness>
            <friction>0.4</friction>
        </dynamics>
    </axis>
    </joint>
    <!--========================================================-->
    <!-- link_gripper_r -->
    <link name='link_gripper_r'>
    <pose relative_to='joint_left'>0 0 0 0 -0 0</pose>
    <inertial>
        <pose>0 0.01369 0.00538 0 -0 0</pose>
        <mass>0.05</mass>
        <inertia>
            <ixx>0.0001</ixx>
            <ixy>0</ixy>
            <ixz>0</ixz>
            <iyy>0.0001</iyy>
            <iyz>0</iyz>
            <izz>0.0001</izz>
        </inertia>
    </inertial>
    <surface>
            <friction>
                <ode>
                    <mu1>10.0</mu1>
                    <mu2>10.0</mu2>
                </ode>
            </friction>
            <contact>
                <ode>
                    <kp>10000.0</kp>
                    <kp>10.0</kp>
                    <min_depth>0.001</min_depth>
                </ode>
            </contact>
        </surface>
    <collision name='link_gripper_r_fixed_joint_lump__hand_f_collision_collision'>
        <pose>0 0.0595 -0.015 1.5708 -1.5708 0</pose>
        <geometry>
        <mesh>
            <scale>1 1 1</scale>
            <uri>model://robot_description/meshes/coll/hand_f.dae</uri>
        </mesh>
        </geometry>
    </collision>
    <visual name='link_gripper_r_fixed_joint_lump__hand_f_visual'>
        <pose>0 0.0595 -0.015 1.5708 -1.5708 0</pose>
        <geometry>
        <mesh>
            <scale>1 1 1</scale>
            <uri>model://robot_description/meshes/dae/hand_f.dae</uri>
        </mesh>
        </geometry>
    </visual>
    <self_collide>1</self_collide>
    </link>
    <!--========================================================-->
    <!-- joint_right -->
    <joint name='joint_right' type='prismatic'>
    <pose relative_to='link_j6'>-0.0155 0 0.062 -1.5708 0 1.5708</pose>
    <parent>link_j6</parent>
    <child>link_gripper_l</child>
    <axis>
        <xyz>0 0 1</xyz>
        <limit>
            <lower>-0.015</lower>
            <upper>0</upper>
            <effort>100</effort>
            <velocity>1</velocity>
        </limit>
        <dynamics>
            <spring_reference>0</spring_reference>
            <spring_stiffness>0</spring_stiffness>
            <friction>0.4</friction>
        </dynamics>
    </axis>
    </joint>
    <!--========================================================-->
    <!-- link_gripper_l -->
    <link name='link_gripper_l'>
    <pose relative_to='joint_right'>0 0 0 0 -0 0</pose>
    <inertial>
        <pose>0 0.01319 0.00538 0 -0 0</pose>
        <mass>0.05</mass>
        <inertia>
            <ixx>0.0001</ixx>
            <ixy>0</ixy>
            <ixz>0</ixz>
            <iyy>0.0001</iyy>
            <iyz>0</iyz>
            <izz>0.0001</izz>
        </inertia>
    </inertial>
    <surface>
            <friction>
                <ode>
                    <mu1>10</mu1>
                    <mu2>10</mu2>
                </ode>
            </friction>
            <contact>
                <ode>
                    <kp>10000.0</kp>
                    <kp>10.0</kp>
                    <min_depth>0.001</min_depth>
                </ode>
            </contact>
        </surface>
    <collision name='link_gripper_l_fixed_joint_lump__hand_f2_collision_collision'>
        <pose>0 0.059 -0.015 1.5708 1.5708 0</pose>
        <geometry>
        <mesh>
            <scale>1 1 1</scale>
            <uri>model://robot_description/meshes/coll/hand_f2.dae</uri>
        </mesh>
        </geometry>
    </collision>
    <visual name='link_gripper_l_fixed_joint_lump__hand_f2_visual'>
        <pose>0 0.059 -0.015 1.5708 1.5708 0</pose>
        <geometry>
        <mesh>
            <scale>1 1 1</scale>
            <uri>model://robot_description/meshes/dae/hand_f2.dae</uri>
        </mesh>
        </geometry>
    </visual>
    <self_collide>1</self_collide>
    </link>
    <!--========================================================-->
    <!-- Applicazione plugin a ogni joint per permettere il funzionamento del controller-->
        <plugin filename="ignition-gazebo-joint-position-controller-system" name="ignition::gazebo::systems::JointPositionController">
            <joint_name>joint1</joint_name>
            <p_gain>500</p_gain>
            <d_gain>0</d_gain>
            <i_gain>0</i_gain>
            <i_min>-1</i_min>
            <i_max>1</i_max>
        </plugin>
        <plugin filename="ignition-gazebo-joint-position-controller-system" name="ignition::gazebo::systems::JointPositionController">
            <joint_name>joint2</joint_name>
            <p_gain>500</p_gain>
            <d_gain>0</d_gain>
            <i_gain>0</i_gain>
            <i_min>-1</i_min>
            <i_max>1</i_max>
        </plugin>
        <plugin filename="ignition-gazebo-joint-position-controller-system" name="ignition::gazebo::systems::JointPositionController">
            <joint_name>joint3</joint_name>
            <p_gain>500</p_gain>
            <d_gain>0</d_gain>
            <i_gain>0</i_gain>
            <i_min>-1</i_min>
            <i_max>1</i_max>
        </plugin>
        <plugin filename="ignition-gazebo-joint-position-controller-system" name="ignition::gazebo::systems::JointPositionController">
            <joint_name>joint4</joint_name>
            <p_gain>500</p_gain>
            <d_gain>0</d_gain>
            <i_gain>0</i_gain>
            <i_min>-1</i_min>
            <i_max>1</i_max>
        </plugin>
        <plugin filename="ignition-gazebo-joint-position-controller-system" name="ignition::gazebo::systems::JointPositionController">
            <joint_name>joint5</joint_name>
            <p_gain>500</p_gain>
            <d_gain>0</d_gain>
            <i_gain>0</i_gain>
            <i_min>-1</i_min>
            <i_max>1</i_max>
        </plugin>
        <plugin filename="ignition-gazebo-joint-position-controller-system" name="ignition::gazebo::systems::JointPositionController">
            <joint_name>joint6</joint_name>
            <p_gain>500</p_gain>
            <d_gain>0</d_gain>
            <i_gain>0</i_gain>
            <i_min>-1</i_min>
            <i_max>1</i_max>
        </plugin>
        <plugin filename="ignition-gazebo-joint-position-controller-system" name="ignition::gazebo::systems::JointPositionController">
            <joint_name>joint_left</joint_name>
            <p_gain>500</p_gain>
            <d_gain>10</d_gain>
            <i_gain>0</i_gain>
            <i_min>-1</i_min>
            <i_max>1</i_max>
        </plugin>
        <plugin filename="ignition-gazebo-joint-position-controller-system" name="ignition::gazebo::systems::JointPositionController">
            <joint_name>joint_right</joint_name>
            <p_gain>500</p_gain>
            <d_gain>10</d_gain>
            <i_gain>0</i_gain>
            <i_min>-1</i_min>
            <i_max>1</i_max>
        </plugin>
    <!--========================================================-->

    <!-- applicazione del plugin per la visualizzazione della posizione dei joint tramite topic-->
        <plugin filename="gz-sim-joint-state-publisher-system" name="gz::sim::systems::JointStatePublisher">
            <topic>/joint_states</topic>
        </plugin>
</model>
</sdf>