<robot name="Cobotta" version="1.0">
  <joint name="camera_link_joint" type="fixed">
    <origin rpy="-0.00000 1.57080 0.00000" xyz="0.00000 -0.01300 0.02250"/>
    <parent link="link_j5"/>
    <child link="camera_link"/>
  </joint>
  <joint name="joint1" type="continuous">
    <limit lower="0.00000" upper="0.00000" effort="0.00000" velocity="5.00000"/>
    <origin rpy="0.00000 0.00000 0.00000" xyz="0.00000 0.00000 0.10800"/>
    <parent link="ROOT"/>
    <child link="link_j1"/>
    <axis xyz="0.00000 0.00000 1.00000"/>
  </joint>
  <joint name="joint2" type="continuous">
    <limit lower="0.00000" upper="0.00000" effort="0.00000" velocity="5.00000"/>
    <origin rpy="-0.00000 1.57080 0.00000" xyz="0.06200 0.00000 0.07200"/>
    <parent link="link_j1"/>
    <child link="link_j2"/>
    <axis xyz="0.00000 0.00000 1.00000"/>
  </joint>
  <joint name="joint3" type="continuous">
    <limit lower="0.00000" upper="0.00000" effort="0.00000" velocity="5.00000"/>
    <origin rpy="3.14159 -0.00000 3.14159" xyz="-0.16500 0.00000 0.00000"/>
    <parent link="link_j2"/>
    <child link="link_j3"/>
    <axis xyz="0.00000 0.00000 1.00000"/>
  </joint>
  <joint name="joint4" type="continuous">
    <limit lower="0.00000" upper="0.00000" effort="0.00000" velocity="5.00000"/>
    <origin rpy="1.57080 1.57080 0.00000" xyz="0.01200 -0.08800 0.04200"/>
    <parent link="link_j3"/>
    <child link="link_j4"/>
    <axis xyz="0.00000 0.00000 1.00000"/>
  </joint>
  <joint name="joint5" type="continuous">
    <limit lower="0.00000" upper="0.00000" effort="0.00000" velocity="5.00000"/>
    <origin rpy="-1.57080 0.00000 1.57080" xyz="-0.04200 0.00000 0.08900"/>
    <parent link="link_j4"/>
    <child link="link_j5"/>
    <axis xyz="0.00000 0.00000 1.00000"/>
  </joint>
  <joint name="joint6" type="continuous">
    <limit lower="0.00000" upper="0.00000" effort="0.00000" velocity="5.00000"/>
    <origin rpy="1.57080 1.57080 0.00000" xyz="0.00000 -0.04000 0.02250"/>
    <parent link="link_j5"/>
    <child link="link_j6"/>
    <axis xyz="0.00000 0.00000 1.00000"/>
  </joint>
  <joint name="joint_left" type="prismatic">
    <limit lower="-0.05000" upper="0.00000" effort="0.00000" velocity="5.00000"/>
    <origin rpy="-1.57080 -0.00000 -1.57080" xyz="0.01450 0.00000 0.06250"/>
    <parent link="link_j6"/>
    <child link="link_gripper_r"/>
    <axis xyz="0.00000 0.00000 1.00000"/>
  </joint>
  <joint name="joint_right" type="prismatic">
    <limit lower="-0.05000" upper="0.00000" effort="0.00000" velocity="5.00000"/>
    <origin rpy="-1.57080 0.00000 1.57080" xyz="-0.01550 0.00000 0.06200"/>
    <parent link="link_j6"/>
    <child link="link_gripper_l"/>
    <axis xyz="0.00000 0.00000 1.00000"/>
  </joint>
  <joint name="new_link.001_joint" type="fixed">
    <origin rpy="0.00000 0.00000 0.00000" xyz="0.00000 0.00000 0.00000"/>
    <parent link="link_root"/>
    <child link="ROOT"/>
  </joint>
  <link name="ROOT">
    <collision name="base_collision">
      <origin rpy="1.57080 0.00000 0.00000" xyz="0.00000 0.00000 0.00000"/>
      <geometry>
        <mesh filename="file:///home/thomas/git/Cobotta/meshes/coll/base.dae" scale="1.00000 1.00000 1.00000"/>
      </geometry>
    </collision>
    <inertial>
      <inertia ixx="0.01954" ixy="-0.00370" ixz="0.00097" iyy="0.00571" iyz="0.00388" izz="0.02017"/>
      <origin rpy="0.00000 0.00000 0.00000" xyz="0.00056 0.02230 0.04527"/>
      <mass value="2.00000"/>
    </inertial>
    <visual name="base">
      <origin rpy="1.57080 0.00000 0.00000" xyz="0.00000 0.00000 0.00000"/>
      <material name="Materiale.003"/>
      <geometry>
        <mesh filename="file:///home/thomas/git/Cobotta/meshes/dae/base.dae" scale="1.00000 1.00000 1.00000"/>
      </geometry>
    </visual>
  </link>
  <link name="camera_link">
    <sensor name="camera" type="camera">
      <origin rpy="1.57080 1.57080 0.00000" xyz="0.00000 -0.02800 0.05600"/>
      <parent link="camera_link"/>
      <camera>
        <image>
          <width>1080</width>
          <height>1920</height>
          <hfov>1.57080</hfov>
        </image>
      </camera>
      <plugin name="camera_controller" filename="libgazebo_ros_camera.so">
	    <frame_name>camera_link</frame_name>
	</plugin>
    </sensor>
    <inertial>
      <inertia ixx="0.00001" ixy="0.00000" ixz="0.00000" iyy="0.00001" iyz="0.00000" izz="0.00001"/>
      <origin rpy="0.00000 0.00000 0.00000" xyz="0.00000 0.00000 0.00000"/>
      <mass value="0.00001"/>
    </inertial>
    <visual name="CAMERA_SET2_ASM">
      <origin rpy="1.57080 0.00000 0.00000" xyz="0.04450 0.19000 -0.35700"/>
      <material name="Materiale.001"/>
      <geometry>
        <mesh filename="file:///home/thomas/git/Cobotta/meshes/dae/CAMERA_SET2_ASM.dae" scale="1.00000 1.00000 1.00000"/>
      </geometry>
    </visual>
  </link>
  <link name="link_gripper_l">
    <collision name="hand_f2_collision">
      <origin rpy="1.57080 1.57080 0.00000" xyz="-0.00000 0.05900 -0.01500"/>
      <geometry>
        <mesh filename="file:///home/thomas/git/Cobotta/meshes/coll/hand_f2.dae" scale="1.00000 1.00000 1.00000"/>
      </geometry>
    </collision>
    <inertial>
      <inertia ixx="0.00001" ixy="0.00000" ixz="0.00000" iyy="0.00001" iyz="0.00000" izz="0.00001"/>
      <origin rpy="0.00000 0.00000 0.00000" xyz="-0.00000 0.01319 0.00538"/>
      <mass value="0.05000"/>
    </inertial>
    <visual name="hand_f2">
      <origin rpy="1.57080 1.57080 0.00000" xyz="-0.00000 0.05900 -0.01500"/>
      <material name="Materiale.009"/>
      <geometry>
        <mesh filename="file:///home/thomas/git/Cobotta/meshes/dae/hand_f2.dae" scale="1.00000 1.00000 1.00000"/>
      </geometry>
    </visual>
  </link>
  <link name="link_gripper_r">
    <collision name="hand_f_collision">
      <origin rpy="1.57080 -1.57080 0.00000" xyz="0.00000 0.05950 -0.01500"/>
      <geometry>
        <mesh filename="file:///home/thomas/git/Cobotta/meshes/coll/hand_f.dae" scale="1.00000 1.00000 1.00000"/>
      </geometry>
    </collision>
    <inertial>
      <inertia ixx="0.00001" ixy="-0.00000" ixz="0.00000" iyy="0.00001" iyz="-0.00000" izz="0.00001"/>
      <origin rpy="0.00000 0.00000 0.00000" xyz="-0.00000 0.01369 0.00538"/>
      <mass value="0.05000"/>
    </inertial>
    <visual name="hand_f">
      <origin rpy="1.57080 -1.57080 0.00000" xyz="0.00000 0.05950 -0.01500"/>
      <material name="Materiale.008"/>
      <geometry>
        <mesh filename="file:///home/thomas/git/Cobotta/meshes/dae/hand_f.dae" scale="1.00000 1.00000 1.00000"/>
      </geometry>
    </visual>
  </link>
  <link name="link_j1">
    <collision name="j2_collision">
      <origin rpy="1.57080 0.00000 0.00000" xyz="0.00000 0.00000 -0.10800"/>
      <geometry>
        <mesh filename="file:///home/thomas/git/Cobotta/meshes/coll/j2.dae" scale="1.00000 1.00000 1.00000"/>
      </geometry>
    </collision>
    <inertial>
      <inertia ixx="0.00068" ixy="0.00000" ixz="-0.00009" iyy="0.00078" iyz="0.00000" izz="0.00057"/>
      <origin rpy="0.00000 0.00000 0.00000" xyz="0.00668 -0.00000 0.04965"/>
      <mass value="0.50000"/>
    </inertial>
    <visual name="j2">
      <origin rpy="1.57080 0.00000 0.00000" xyz="0.00000 0.00000 -0.10800"/>
      <material name="Materiale.005"/>
      <geometry>
        <mesh filename="file:///home/thomas/git/Cobotta/meshes/dae/j2.dae" scale="1.00000 1.00000 1.00000"/>
      </geometry>
    </visual>
  </link>
  <link name="link_j2">
    <collision name="j1Starm_collision">
      <origin rpy="1.57080 -1.57080 0.00000" xyz="0.18000 0.00000 -0.06200"/>
      <geometry>
        <mesh filename="file:///home/thomas/git/Cobotta/meshes/coll/j1Starm.dae" scale="1.00000 1.00000 1.00000"/>
      </geometry>
    </collision>
    <inertial>
      <inertia ixx="0.00482" ixy="-0.00008" ixz="-0.00003" iyy="0.00462" iyz="-0.00003" izz="0.00075"/>
      <origin rpy="0.00000 0.00000 0.00000" xyz="-0.07592 0.02475 0.03838"/>
      <mass value="1.00000"/>
    </inertial>
    <visual name="j1Starm">
      <origin rpy="1.57080 -1.57080 0.00000" xyz="0.18000 0.00000 -0.06200"/>
      <material name="Materiale"/>
      <geometry>
        <mesh filename="file:///home/thomas/git/Cobotta/meshes/dae/j1Starm.dae" scale="1.00000 1.00000 1.00000"/>
      </geometry>
    </visual>
  </link>
  <link name="link_j3">
    <collision name="j34_collision">
      <origin rpy="1.57080 1.57080 0.00000" xyz="-0.34500 0.00000 0.06200"/>
      <geometry>
        <mesh filename="file:///home/thomas/git/Cobotta/meshes/coll/j34.dae" scale="1.00000 1.00000 1.00000"/>
      </geometry>
    </collision>
    <inertial>
      <inertia ixx="0.00040" ixy="-0.00003" ixz="0.00001" iyy="0.00018" iyz="0.00004" izz="0.00041"/>
      <origin rpy="0.00000 0.00000 0.00000" xyz="0.00526 -0.02675 0.03861"/>
      <mass value="0.30000"/>
    </inertial>
    <visual name="j34">
      <origin rpy="1.57080 1.57080 0.00000" xyz="-0.34500 0.00000 0.06200"/>
      <material name="Materiale.004"/>
      <geometry>
        <mesh filename="file:///home/thomas/git/Cobotta/meshes/dae/j34.dae" scale="1.00000 1.00000 1.00000"/>
      </geometry>
    </visual>
  </link>
  <link name="link_j4">
    <collision name="j2ndarm_collision">
      <origin rpy="0.00000 0.00000 0.00000" xyz="-0.02000 -0.35700 -0.08800"/>
      <geometry>
        <mesh filename="file:///home/thomas/git/Cobotta/meshes/coll/j2ndarm.dae" scale="1.00000 1.00000 1.00000"/>
      </geometry>
    </collision>
    <inertial>
      <inertia ixx="0.00038" ixy="-0.00002" ixz="-0.00000" iyy="0.00013" iyz="-0.00000" izz="0.00039"/>
      <origin rpy="0.00000 0.00000 0.00000" xyz="-0.00143 -0.00000 0.05394"/>
      <mass value="0.30000"/>
    </inertial>
    <visual name="j2ndarm">
      <origin rpy="0.00000 0.00000 0.00000" xyz="-0.02000 -0.35700 -0.08800"/>
      <material name="Materiale.006"/>
      <geometry>
        <mesh filename="file:///home/thomas/git/Cobotta/meshes/dae/j2ndarm.dae" scale="1.00000 1.00000 1.00000"/>
      </geometry>
    </visual>
  </link>
  <link name="link_j5">
    <collision name="j6_collision">
      <origin rpy="1.57080 1.57080 0.00000" xyz="-0.35700 0.17700 -0.02200"/>
      <geometry>
        <mesh filename="file:///home/thomas/git/Cobotta/meshes/coll/j6.dae" scale="1.00000 1.00000 1.00000"/>
      </geometry>
    </collision>
    <inertial>
      <inertia ixx="0.00008" ixy="-0.00001" ixz="0.00001" iyy="0.00008" iyz="0.00001" izz="0.00006"/>
      <origin rpy="0.00000 0.00000 0.00000" xyz="-0.00010 -0.00840 0.01804"/>
      <mass value="0.10000"/>
    </inertial>
    <visual name="j6">
      <origin rpy="1.57080 1.57080 0.00000" xyz="-0.35700 0.17700 -0.02200"/>
      <material name="Materiale.007"/>
      <geometry>
        <mesh filename="file:///home/thomas/git/Cobotta/meshes/dae/j6.dae" scale="1.00000 1.00000 1.00000"/>
      </geometry>
    </visual>
  </link>
  <link name="link_j6">
    <collision name="hand_collision">
      <origin rpy="0.00000 0.00000 0.00000" xyz="-0.00050 0.00000 0.00100"/>
      <geometry>
        <mesh filename="file:///home/thomas/git/Cobotta/meshes/coll/hand.dae" scale="1.00000 1.00000 1.00000"/>
      </geometry>
    </collision>
    <inertial>
      <inertia ixx="0.00003" ixy="0.00000" ixz="-0.00000" iyy="0.00004" iyz="0.00000" izz="0.00003"/>
      <origin rpy="0.00000 0.00000 0.00000" xyz="-0.00050 0.00000 0.02106"/>
      <mass value="0.10000"/>
    </inertial>
    <visual name="hand">
      <origin rpy="0.00000 0.00000 0.00000" xyz="-0.00050 0.00000 0.00100"/>
      <material name="Materiale.002"/>
      <geometry>
        <mesh filename="file:///home/thomas/git/Cobotta/meshes/dae/hand.dae" scale="1.00000 1.00000 1.00000"/>
      </geometry>
    </visual>
  </link>
  <link name="link_root">
    <inertial>
      <inertia ixx="0.00001" ixy="0.00000" ixz="0.00000" iyy="0.00001" iyz="0.00000" izz="0.00001"/>
      <origin rpy="0.00000 0.00000 0.00000" xyz="0.00000 0.00000 0.00000"/>
      <mass value="0.00001"/>
    </inertial>
  </link>
  <material name="Materiale">
    <color rgba="0.78039 0.78039 0.78039 1.00000"/>
  </material>
  <material name="Materiale.001">
    <color rgba="0.80000 0.80000 0.80000 1.00000"/>
  </material>
  <material name="Materiale.002">
    <color rgba="0.80000 0.80000 0.80000 1.00000"/>
  </material>
  <material name="Materiale.003">
    <color rgba="0.80000 0.80000 0.80000 1.00000"/>
  </material>
  <material name="Materiale.004">
    <color rgba="0.80000 0.80000 0.80000 1.00000"/>
  </material>
  <material name="Materiale.005">
    <color rgba="0.80000 0.80000 0.80000 1.00000"/>
  </material>
  <material name="Materiale.006">
    <color rgba="0.80000 0.80000 0.80000 1.00000"/>
  </material>
  <material name="Materiale.007">
    <color rgba="0.80000 0.80000 0.80000 1.00000"/>
  </material>
  <material name="Materiale.008">
    <color rgba="0.80000 0.80000 0.80000 1.00000"/>
  </material>
  <material name="Materiale.009">
    <color rgba="0.80000 0.80000 0.80000 1.00000"/>
  </material>
</robot>
